Workbook

Sheet Project Overview
A2: Project: Insurance Product Rules Testing and Premium Validation Project
A3: An Excel project that tests premium calculations across 1,000 synthetic auto insurance policies.
A6: Overview: | B6: This project simulates the process of testing an auto insurance rating system in Excel.
B8: I first created a rate book containing coverage base rates and the different factors that could affect a policy’s premium. These included the driver’s age, years of driving experience, accident history, annual mileage, location, vehicle value and characteristics, coverage selections, deductibles, limits, discounts, and a rate change that takes effect on January 1, 2026.
B11: I then created 1,000 test policies with different combinations of these characteristics and coverage selections.
B14: The Test Cases tab contains the original test population. Those policies are carried into the Premium Validation tab, where the applicable base rate and rating factors are added. The workbook then calculates an expected premium for each policy and compares it with a simulated system-generated premium.
B17: Each test case receives a PASS or FAIL result based on the difference between the two premiums. The workbook also identifies the factor that was most likely applied incorrectly when a policy fails.
B20: The QA Summary shows the overall testing results and breaks down the failed cases by likely cause. The Issue Log contains all 39 failed cases, along with the system premium, expected premium, difference, likely issue, recommended action, and current status.
B23: All policies, rating factors, premiums, system results, and issues in this project are synthetic. They were created for educational and portfolio purposes and do not represent the actual rates or pricing methods of any other insurance company.

Sheet Rate Book
A1: Age: | C1: Ageband | D1: Ageband Factor
C2: 16-24 | D2: 1.32
C3: 25-34 | D3: 1.23
C4: 35-44 | D4: 1
C5: 45-54 | D5: 1.07
C6: 55-64 | D6: 1.12
C7: 65+ | D7: 1.27
A10: Years Driving: | C10: Years Driving | D10: Years Driving Factor
C11: 0 | D11: 1.87
C12: 1 | D12: 1.64
C13: 2 | D13: 1.41
C14: 3 | D14: 1.22
C15: 4 | D15: 1.15
C16: 5 | D16: 1.07
C17: 6 | D17: 1
C18: 7 | D18: 0.95
C19: 8+ | D19: 0.93
A22: At Fault Accidents: | C22: At Fault Accidents | D22: At Fault Accident Factor
A23: (in last 36 months) | C23: 0 | D23: 1
C24: 1 | D24: 1.34
C25: 2 | D25: 1.55
C26: 3 | D26: 1.82
C27: 4 | D27: 2.12
C28: 5+ | D28: 2.47
A31: Usage-Based Insurance: | C31: Usage-Based Insurance | D31: Usage-Based Insurance Discount
C32: No | D32: 1
C33: Yes (Low Score) | D33: 0.95
C34: Yes (Medium Score) | D34: 0.8
C35: Yes (High Score) | D35: 0.65
A38: Yearly Miles: | C38: Yearly Miles | D38: Yearly Miles Factor
C39: 0-4,999 | D39: 0.82
C40: 5,000-8,499 | D40: 0.93
C41: 8,500-13,499 | D41: 1
C42: 13,500-16,999 | D42: 1.18
C43: 17,000+ | D43: 1.31
A46: City/Zip Code: | C46: City/Zip Code | D46: City/Zip Code Factor
C47: DTLA (90012) | D47: 1.26
C48: Koreatown (90006) | D48: 1.21
C49: Costa Mesa (92626) | D49: 0.92
C50: Hollywood (90028) | D50: 1.19
...

Sheet Test Cases
A1: PolicyID | B1: Effective Date | C1: Coverage | D1: Ageband | E1: Years Driving | F1: At Fault Accidents | G1: Usage-Based Insurance | H1: Yearly Miles | I1: City/Zip Code | J1: Vehicle Price | K1: Exotic Car | L1: Difficult Parts | M1: High Theft Rate | N1: Advanced Safety Features | O1: Deductible Applies | P1: Coverage Limit Applies | Q1: Deductible | R1: Coverage Limit | S1: Good Student Discount | T1: Good Driver Discount | U1: Multi Policy Discount | V1: Loyal Customer Discount | W1: Organization Discount
A2: P0001 | B2: 45908 | C2: Comprehensive | D2: 25-34 | E2: 1 | F2: 5+ | G2: Yes (Medium Score) | H2: 5,000-8,499 | I2: Costa Mesa (92626) | J2: $5,000-$14,999 | K2: No | L2: No | M2: No | N2: No | O2: =INDEX(CoverageTable[Deductible Applies],MATCH(Table18[[#This Row],[Coverage]],CoverageTable[Coverage],0)) -> Yes | P2: =INDEX(CoverageTable[Coverage Limit Applies],MATCH(Table18[[#This Row],[Coverage]],CoverageTable[Coverage],0)) -> No | Q2: Yes (Medium) | R2: No | S2: Yes | T2: No | U2: No | V2: No | W2: Yes
A3: P0002 | B3: 45889 | C3: Rental Car Reinbursement | D3: 16-24 | E3: 5 | F3: 4 | G3: No | H3: 8,500-13,499 | I3: West Hollywood (90046) | J3: $85,000-$149,999 | K3: No | L3: Yes | M3: No | N3: No | O3: =INDEX(CoverageTable[Deductible Applies],MATCH(Table18[[#This Row],[Coverage]],CoverageTable[Coverage],0)) -> No | P3: =INDEX(CoverageTable[Coverage Limit Applies],MATCH(Table18[[#This Row],[Coverage]],CoverageTable[Coverage],0)) -> Yes | Q3: No | R3: Yes (High) | S3: No | T3: No | U3: Yes | V3: No | W3: No
A4: P0003 | B4: 45946 | C4: Rental Car Reinbursement | D4: 55-64 | E4: 5 | F4: 5+ | G4: No | H4: 5,000-8,499 | I4: Anaheim (92801) | J4: $5,000-$14,999 | K4: No | L4: No | M4: No | N4: No | O4: =INDEX(CoverageTable[Deductible Applies],MATCH(Table18[[#This Row],[Coverage]],CoverageTable[Coverage],0)) -> No | P4: =INDEX(CoverageTable[Coverage Limit Applies],MATCH(Table18[[#This Row],[Coverage]],CoverageTable[Coverage],0)) -> Yes | Q4: No | R4: Yes (High) | S4: No | T4: No | U4: No | V4: No | W4: No
A5: P0004 | B5: 46106 | C5: Comprehensive | D5: 65+ | E5: 8+ | F5: 2 | G5: Yes (Medium Score) | H5: 17,000+ | I5: Westminster (92655) | J5: $0-$4,999 | K5: No | L5: No | M5: No | N5: Yes | O5: =INDEX(CoverageTable[Deductible Applies],MATCH(Table18[[#This Row],[Coverage]],CoverageTable[Coverage],0)) -> Yes | P5: =INDEX(CoverageTable[Coverage Limit Applies],MATCH(Table18[[#This Row],[Coverage]],CoverageTable[Coverage],0)) -> No | Q5: Yes (Low) | R5: No | S5: No | T5: Yes | U5: Yes | V5: No | W5: No
A6: P0005 | B6: 46023 | C6: Collision | D6: 55-64 | E6: 7 | F6: 3 | G6: Yes (Medium Score) | H6: 13,500-16,999 | I6: Culver City (90066) | J6: $25,000-$44,999 | K6: No | L6: No | M6: No | N6: Yes | O6: =INDEX(CoverageTable[Deductible Applies],MATCH(Table18[[#This Row],[Coverage]],CoverageTable[Coverage],0)) -> Yes | P6: =INDEX(CoverageTable[Coverage Limit Applies],MATCH(Table18[[#This Row],[Coverage]],CoverageTable[Coverage],0)) -> No | Q6: Yes (Low) | R6: No | S6: No | T6: No | U6: Yes | V6: No | W6: No
A7: P0006 | B7: 45924 | C7: Collision | D7: 25-34 | E7: 8+ | F7: 4 | G7: No | H7: 17,000+ | I7: Westminster (92655) | J7: $5,000-$14,999 | K7: No | L7: No | M7: No | N7: No | O7: =INDEX(CoverageTable[Deductible Applies],MATCH(Table18[[#This Row],[Coverage]],CoverageTable[Coverage],0)) -> Yes | P7: =INDEX(CoverageTable[Coverage Limit Applies],MATCH(Table18[[#This Row],[Coverage]],CoverageTable[Coverage],0)) -> No | Q7: Yes (High) | R7: No | S7: No | T7: No | U7: No | V7: No | W7: No
A8: P0007 | B8: 46120 | C8: Rental Car Reinbursement | D8: 35-44 | E8: 5 | F8: 3 | G8: No | H8: 0-4,999 | I8: Silverlake (90026 ) | J8: $85,000-$149,999 | K8: No | L8: No | M8: No | N8: No | O8: =INDEX(CoverageTable[Deductible Applies],MATCH(Table18[[#This Row],[Coverage]],CoverageTable[Coverage],0)) -> No | P8: =INDEX(CoverageTable[Coverage Limit Applies],MATCH(Table18[[#This Row],[Coverage]],CoverageTable[Coverage],0)) -> Yes | Q8: No | R8: Yes (Low) | S8: No | T8: No | U8: No | V8: No | W8: No
A9: P0008 | B9: 46143 | C9: Liability | D9: 25-34 | E9: 7 | F9: 2 | G9: Yes (Medium Score) | H9: 8,500-13,499 | I9: Compton (90220) | J9: $45,000-$84,999 | K9: No | L9: No | M9: No | N9: Yes | O9: =INDEX(CoverageTable[Deductible Applies],MATCH(Table18[[#This Row],[Coverage]],CoverageTable[Coverage],0)) -> No | P9: =INDEX(CoverageTable[Coverage Limit Applies],MATCH(Table18[[#This Row],[Coverage]],CoverageTable[Coverage],0)) -> Yes | Q9: No | R9: Yes (Medium) | S9: Yes | T9: No | U9: No | V9: No | W9: No
A10: P0009 | B10: 46072 | C10: Liability | D10: 35-44 | E10: 6 | F10: 3 | G10: Yes (High Score) | H10: 17,000+ | I10: Newport Beach (92603) | J10: $85,000-$149,999 | K10: No | L10: No | M10: No | N10: No | O10: =INDEX(CoverageTable[Deductible Applies],MATCH(Table18[[#This Row],[Coverage]],CoverageTable[Coverage],0)) -> No | P10: =INDEX(CoverageTable[Coverage Limit Applies],MATCH(Table18[[#This Row],[Coverage]],CoverageTable[Coverage],0)) -> Yes | Q10: No | R10: Yes (Medium) | S10: Yes | T10: Yes | U10: Yes | V10: No | W10: Yes
A11: P0010 | B11: 45997 | C11: Liability | D11: 25-34 | E11: 8+ | F11: 2 | G11: No | H11: 5,000-8,499 | I11: Huntington Beach (90742) | J11: $15,000-$24,999 | K11: No | L11: No | M11: No | N11: No | O11: =INDEX(CoverageTable[Deductible Applies],MATCH(Table18[[#This Row],[Coverage]],CoverageTable[Coverage],0)) -> No | P11: =INDEX(CoverageTable[Coverage Limit Applies],MATCH(Table18[[#This Row],[Coverage]],CoverageTable[Coverage],0)) -> Yes | Q11: No | R11: Yes (Medium) | S11: No | T11: No | U11: No | V11: No | W11: Yes
A12: P0011 | B12: 46063 | C12: Comprehensive | D12: 35-44 | E12: 2 | F12: 1 | G12: No | H12: 5,000-8,499 | I12: Culver City (90066) | J12: $15,000-$24,999 | K12: Yes | L12: No | M12: No | N12: No | O12: =INDEX(CoverageTable[Deductible Applies],MATCH(Table18[[#This Row],[Coverage]],CoverageTable[Coverage],0)) -> Yes | P12: =INDEX(CoverageTable[Coverage Limit Applies],MATCH(Table18[[#This Row],[Coverage]],CoverageTable[Coverage],0)) -> No | Q12: Yes (High) | R12: No | S12: No | T12: No | U12: No | V12: Yes | W12: No
A13: P0012 | B13: 46097 | C13: Liability | D13: 65+ | E13: 5 | F13: 5+ | G13: Yes (Low Score) | H13: 17,000+ | I13: West Hollywood (90046) | J13: $15,000-$24,999 | K13: No | L13: No | M13: Yes | N13: Yes | O13: =INDEX(CoverageTable[Deductible Applies],MATCH(Table18[[#This Row],[Coverage]],CoverageTable[Coverage],0)) -> No | P13: =INDEX(CoverageTable[Coverage Limit Applies],MATCH(Table18[[#This Row],[Coverage]],CoverageTable[Coverage],0)) -> Yes | Q13: No | R13: Yes (Medium) | S13: Yes | T13: Yes | U13: No | V13: No | W13: No
A14: P0013 | B14: 46139 | C14: Uninsured Motorist | D14: 45-54 | E14: 1 | F14: 3 | G14: Yes (Low Score) | H14: 13,500-16,999 | I14: Torrance (90248) | J14: $5,000-$14,999 | K14: Yes | L14: No | M14: No | N14: Yes | O14: =INDEX(CoverageTable[Deductible Applies],MATCH(Table18[[#This Row],[Coverage]],CoverageTable[Coverage],0)) -> No | P14: =INDEX(CoverageTable[Coverage Limit Applies],MATCH(Table18[[#This Row],[Coverage]],CoverageTable[Coverage],0)) -> Yes | Q14: No | R14: Yes (Medium) | S14: No | T14: No | U14: No | V14: No | W14: No
A15: P0014 | B15: 45901 | C15: Liability | D15: 55-64 | E15: 5 | F15: 3 | G15: Yes (High Score) | H15: 17,000+ | I15: Costa Mesa (92626) | J15: $45,000-$84,999 | K15: No | L15: No | M15: No | N15: Yes | O15: =INDEX(CoverageTable[Deductible Applies],MATCH(Table18[[#This Row],[Coverage]],CoverageTable[Coverage],0)) -> No | P15: =INDEX(CoverageTable[Coverage Limit Applies],MATCH(Table18[[#This Row],[Coverage]],CoverageTable[Coverage],0)) -> Yes | Q15: No | R15: Yes (Medium) | S15: No | T15: Yes | U15: No | V15: Yes | W15: No
A16: P0015 | B16: 45813 | C16: Liability | D16: 35-44 | E16: 7 | F16: 4 | G16: No | H16: 5,000-8,499 | I16: Long Beach (90712) | J16: $0-$4,999 | K16: No | L16: No | M16: No | N16: Yes | O16: =INDEX(CoverageTable[Deductible Applies],MATCH(Table18[[#This Row],[Coverage]],CoverageTable[Coverage],0)) -> No | P16: =INDEX(CoverageTable[Coverage Limit Applies],MATCH(Table18[[#This Row],[Coverage]],CoverageTable[Coverage],0)) -> Yes | Q16: No | R16: Yes (Medium) | S16: No | T16: No | U16: No | V16: No | W16: Yes
A17: P0016 | B17: 45944 | C17: Collision | D17: 16-24 | E17: 7 | F17: 0 | G17: Yes (Medium Score) | H17: 8,500-13,499 | I17: Fullerton (92832) | J17: $150,000+ | K17: No | L17: No | M17: No | N17: No | O17: =INDEX(CoverageTable[Deductible Applies],MATCH(Table18[[#This Row],[Coverage]],CoverageTable[Coverage],0)) -> Yes | P17: =INDEX(CoverageTable[Coverage Limit Applies],MATCH(Table18[[#This Row],[Coverage]],CoverageTable[Coverage],0)) -> No | Q17: Yes (Medium) | R17: No | S17: No | T17: Yes | U17: No | V17: No | W17: No
A18: P0017 | B18: 45792 | C18: Uninsured Motorist | D18: 65+ | E18: 7 | F18: 1 | G18: Yes (Low Score) | H18: 17,000+ | I18: Compton (90220) | J18: $5,000-$14,999 | K18: No | L18: No | M18: No | N18: Yes | O18: =INDEX(CoverageTable[Deductible Applies],MATCH(Table18[[#This Row],[Coverage]],CoverageTable[Coverage],0)) -> No | P18: =INDEX(CoverageTable[Coverage Limit Applies],MATCH(Table18[[#This Row],[Coverage]],CoverageTable[Coverage],0)) -> Yes | Q18: No | R18: Yes (High) | S18: No | T18: No | U18: No | V18: No | W18: No
A19: P0018 | B19: 45825 | C19: Collision | D19: 65+ | E19: 7 | F19: 1 | G19: No | H19: 0-4,999 | I19: West Hollywood (90046) | J19: $15,000-$24,999 | K19: No | L19: No | M19: No | N19: No | O19: =INDEX(CoverageTable[Deductible Applies],MATCH(Table18[[#This Row],[Coverage]],CoverageTable[Coverage],0)) -> Yes | P19: =INDEX(CoverageTable[Coverage Limit Applies],MATCH(Table18[[#This Row],[Coverage]],CoverageTable[Coverage],0)) -> No | Q19: Yes (Low) | R19: No | S19: No | T19: No | U19: No | V19: No | W19: No
A20: P0019 | B20: 46085 | C20: Uninsured Motorist | D20: 65+ | E20: 3 | F20: 5+ | G20: No | H20: 0-4,999 | I20: Santa Monica (90401) | J20: $15,000-$24,999 | K20: No | L20: Yes | M20: No | N20: Yes | O20: =INDEX(CoverageTable[Deductible Applies],MATCH(Table18[[#This Row],[Coverage]],CoverageTable[Coverage],0)) -> No | P20: =INDEX(CoverageTable[Coverage Limit Applies],MATCH(Table18[[#This Row],[Coverage]],CoverageTable[Coverage],0)) -> Yes | Q20: No | R20: Yes (High) | S20: No | T20: No | U20: No | V20: No | W20: No
A21: P0020 | B21: 45889 | C21: Uninsured Motorist | D21: 25-34 | E21: 6 | F21: 0 | G21: Yes (High Score) | H21: 8,500-13,499 | I21: Compton (90220) | J21: $85,000-$149,999 | K21: No | L21: No | M21: No | N21: Yes | O21: =INDEX(CoverageTable[Deductible Applies],MATCH(Table18[[#This Row],[Coverage]],CoverageTable[Coverage],0)) -> No | P21: =INDEX(CoverageTable[Coverage Limit Applies],MATCH(Table18[[#This Row],[Coverage]],CoverageTable[Coverage],0)) -> Yes | Q21: No | R21: Yes (High) | S21: No | T21: No | U21: No | V21: No | W21: No
A22: P0021 | B22: 45863 | C22: Collision | D22: 16-24 | E22: 1 | F22: 4 | G22: No | H22: 0-4,999 | I22: Westminster (92655) | J22: $0-$4,999 | K22: No | L22: No | M22: No | N22: Yes | O22: =INDEX(CoverageTable[Deductible Applies],MATCH(Table18[[#This Row],[Coverage]],CoverageTable[Coverage],0)) -> Yes | P22: =INDEX(CoverageTable[Coverage Limit Applies],MATCH(Table18[[#This Row],[Coverage]],CoverageTable[Coverage],0)) -> No | Q22: Yes (Low) | R22: No | S22: No | T22: No | U22: No | V22: Yes | W22: No
A23: P0022 | B23: 45961 | C23: Collision | D23: 65+ | E23: 7 | F23: 3 | G23: Yes (Low Score) | H23: 13,500-16,999 | I23: Compton (90220) | J23: $45,000-$84,999 | K23: No | L23: No | M23: Yes | N23: Yes | O23: =INDEX(CoverageTable[Deductible Applies],MATCH(Table18[[#This Row],[Coverage]],CoverageTable[Coverage],0)) -> Yes | P23: =INDEX(CoverageTable[Coverage Limit Applies],MATCH(Table18[[#This Row],[Coverage]],CoverageTable[Coverage],0)) -> No | Q23: Yes (Low) | R23: No | S23: No | T23: Yes | U23: No | V23: No | W23: No
A24: P0023 | B24: 45867 | C24: Collision | D24: 25-34 | E24: 2 | F24: 0 | G24: No | H24: 0-4,999 | I24: Fullerton (92832) | J24: $25,000-$44,999 | K24: No | L24: No | M24: No | N24: No | O24: =INDEX(CoverageTable[Deductible Applies],MATCH(Table18[[#This Row],[Coverage]],CoverageTable[Coverage],0)) -> Yes | P24: =INDEX(CoverageTable[Coverage Limit Applies],MATCH(Table18[[#This Row],[Coverage]],CoverageTable[Coverage],0)) -> No | Q24: Yes (Low) | R24: No | S24: No | T24: Yes | U24: Yes | V24: No | W24: No
A25: P0024 | B25: 45824 | C25: Collision | D25: 65+ | E25: 1 | F25: 0 | G25: No | H25: 13,500-16,999 | I25: Westminster (92655) | J25: $45,000-$84,999 | K25: No | L25: No | M25: Yes | N25: No | O25: =INDEX(CoverageTable[Deductible Applies],MATCH(Table18[[#This Row],[Coverage]],CoverageTable[Coverage],0)) -> Yes | P25: =INDEX(CoverageTable[Coverage Limit Applies],MATCH(Table18[[#This Row],[Coverage]],CoverageTable[Coverage],0)) -> No | Q25: Yes (Medium) | R25: No | S25: No | T25: No | U25: No | V25: No | W25: No
A26: P0025 | B26: 45861 | C26: Collision | D26: 45-54 | E26: 1 | F26: 0 | G26: Yes (High Score) | H26: 8,500-13,499 | I26: Lake Forrest (92609) | J26: $25,000-$44,999 | K26: No | L26: No | M26: No | N26: Yes | O26: =INDEX(CoverageTable[Deductible Applies],MATCH(Table18[[#This Row],[Coverage]],CoverageTable[Coverage],0)) -> Yes | P26: =INDEX(CoverageTable[Coverage Limit Applies],MATCH(Table18[[#This Row],[Coverage]],CoverageTable[Coverage],0)) -> No | Q26: Yes (High) | R26: No | S26: No | T26: No | U26: No | V26: No | W26: No
A27: P0026 | B27: 46043 | C27: Collision | D27: 65+ | E27: 2 | F27: 3 | G27: No | H27: 5,000-8,499 | I27: Culver City (90066) | J27: $150,000+ | K27: No | L27: Yes | M27: No | N27: Yes | O27: =INDEX(CoverageTable[Deductible Applies],MATCH(Table18[[#This Row],[Coverage]],CoverageTable[Coverage],0)) -> Yes | P27: =INDEX(CoverageTable[Coverage Limit Applies],MATCH(Table18[[#This Row],[Coverage]],CoverageTable[Coverage],0)) -> No | Q27: Yes (Low) | R27: No | S27: Yes | T27: No | U27: No | V27: No | W27: No
A28: P0027 | B28: 45927 | C28: Liability | D28: 35-44 | E28: 8+ | F28: 2 | G28: Yes (High Score) | H28: 5,000-8,499 | I28: Silverlake (90026 ) | J28: $5,000-$14,999 | K28: No | L28: No | M28: No | N28: Yes | O28: =INDEX(CoverageTable[Deductible Applies],MATCH(Table18[[#This Row],[Coverage]],CoverageTable[Coverage],0)) -> No | P28: =INDEX(CoverageTable[Coverage Limit Applies],MATCH(Table18[[#This Row],[Coverage]],CoverageTable[Coverage],0)) -> Yes | Q28: No | R28: Yes (High) | S28: No | T28: No | U28: Yes | V28: No | W28: No
A29: P0028 | B29: 45799 | C29: Rental Car Reinbursement | D29: 45-54 | E29: 3 | F29: 1 | G29: Yes (Medium Score) | H29: 13,500-16,999 | I29: Hawthorne (90250) | J29: $85,000-$149,999 | K29: No | L29: No | M29: No | N29: No | O29: =INDEX(CoverageTable[Deductible Applies],MATCH(Table18[[#This Row],[Coverage]],CoverageTable[Coverage],0)) -> No | P29: =INDEX(CoverageTable[Coverage Limit Applies],MATCH(Table18[[#This Row],[Coverage]],CoverageTable[Coverage],0)) -> Yes | Q29: No | R29: Yes (High) | S29: No | T29: No | U29: No | V29: No | W29: Yes
A30: P0029 | B30: 45819 | C30: Rental Car Reinbursement | D30: 25-34 | E30: 5 | F30: 2 | G30: Yes (Low Score) | H30: 13,500-16,999 | I30: Beverly Hills (90035) | J30: $25,000-$44,999 | K30: No | L30: No | M30: No | N30: No | O30: =INDEX(CoverageTable[Deductible Applies],MATCH(Table18[[#This Row],[Coverage]],CoverageTable[Coverage],0)) -> No | P30: =INDEX(CoverageTable[Coverage Limit Applies],MATCH(Table18[[#This Row],[Coverage]],CoverageTable[Coverage],0)) -> Yes | Q30: No | R30: Yes (High) | S30: No | T30: No | U30: No | V30: No | W30: No
A31: P0030 | B31: 45933 | C31: Uninsured Motorist | D31: 25-34 | E31: 3 | F31: 1 | G31: No | H31: 17,000+ | I31: Culver City (90066) | J31: $5,000-$14,999 | K31: No | L31: No | M31: No | N31: Yes | O31: =INDEX(CoverageTable[Deductible Applies],MATCH(Table18[[#This Row],[Coverage]],CoverageTable[Coverage],0)) -> No | P31: =INDEX(CoverageTable[Coverage Limit Applies],MATCH(Table18[[#This Row],[Coverage]],CoverageTable[Coverage],0)) -> Yes | Q31: No | R31: Yes (High) | S31: No | T31: No | U31: Yes | V31: No | W31: No
A32: P0031 | B32: 46047 | C32: Liability | D32: 16-24 | E32: 1 | F32: 0 | G32: Yes (Medium Score) | H32: 5,000-8,499 | I32: Silverlake (90026 ) | J32: $15,000-$24,999 | K32: Yes | L32: No | M32: No | N32: No | O32: =INDEX(CoverageTable[Deductible Applies],MATCH(Table18[[#This Row],[Coverage]],CoverageTable[Coverage],0)) -> No | P32: =INDEX(CoverageTable[Coverage Limit Applies],MATCH(Table18[[#This Row],[Coverage]],CoverageTable[Coverage],0)) -> Yes | Q32: No | R32: Yes (Medium) | S32: No | T32: No | U32: No | V32: No | W32: No
A33: P0032 | B33: 45927 | C33: Collision | D33: 25-34 | E33: 4 | F33: 4 | G33: No | H33: 17,000+ | I33: DTLA (90012) | J33: $5,000-$14,999 | K33: No | L33: No | M33: No | N33: Yes | O33: =INDEX(CoverageTable[Deductible Applies],MATCH(Table18[[#This Row],[Coverage]],CoverageTable[Coverage],0)) -> Yes | P33: =INDEX(CoverageTable[Coverage Limit Applies],MATCH(Table18[[#This Row],[Coverage]],CoverageTable[Coverage],0)) -> No | Q33: Yes (Low) | R33: No | S33: No | T33: Yes | U33: No | V33: No | W33: No
A34: P0033 | B34: 45841 | C34: Liability | D34: 25-34 | E34: 5 | F34: 4 | G34: No | H34: 17,000+ | I34: DTLA (90012) | J34: $0-$4,999 | K34: No | L34: No | M34: No | N34: Yes | O34: =INDEX(CoverageTable[Deductible Applies],MATCH(Table18[[#This Row],[Coverage]],CoverageTable[Coverage],0)) -> No | P34: =INDEX(CoverageTable[Coverage Limit Applies],MATCH(Table18[[#This Row],[Coverage]],CoverageTable[Coverage],0)) -> Yes | Q34: No | R34: Yes (Medium) | S34: No | T34: No | U34: No | V34: No | W34: No
A35: P0034 | B35: 45816 | C35: Liability | D35: 45-54 | E35: 8+ | F35: 4 | G35: Yes (Medium Score) | H35: 5,000-8,499 | I35: Silverlake (90026 ) | J35: $25,000-$44,999 | K35: No | L35: No | M35: No | N35: Yes | O35: =INDEX(CoverageTable[Deductible Applies],MATCH(Table18[[#This Row],[Coverage]],CoverageTable[Coverage],0)) -> No | P35: =INDEX(CoverageTable[Coverage Limit Applies],MATCH(Table18[[#This Row],[Coverage]],CoverageTable[Coverage],0)) -> Yes | Q35: No | R35: Yes (Low) | S35: Yes | T35: No | U35: No | V35: No | W35: No
A36: P0035 | B36: 46131 | C36: Rental Car Reinbursement | D36: 65+ | E36: 5 | F36: 1 | G36: No | H36: 13,500-16,999 | I36: Fullerton (92832) | J36: $15,000-$24,999 | K36: No | L36: No | M36: No | N36: Yes | O36: =INDEX(CoverageTable[Deductible Applies],MATCH(Table18[[#This Row],[Coverage]],CoverageTable[Coverage],0)) -> No | P36: =INDEX(CoverageTable[Coverage Limit Applies],MATCH(Table18[[#This Row],[Coverage]],CoverageTable[Coverage],0)) -> Yes | Q36: No | R36: Yes (Medium) | S36: No | T36: No | U36: No | V36: Yes | W36: No
A37: P0036 | B37: 45872 | C37: Collision | D37: 45-54 | E37: 7 | F37: 0 | G37: No | H37: 8,500-13,499 | I37: Long Beach (90712) | J37: $0-$4,999 | K37: No | L37: No | M37: No | N37: Yes | O37: =INDEX(CoverageTable[Deductible Applies],MATCH(Table18[[#This Row],[Coverage]],CoverageTable[Coverage],0)) -> Yes | P37: =INDEX(CoverageTable[Coverage Limit Applies],MATCH(Table18[[#This Row],[Coverage]],CoverageTable[Coverage],0)) -> No | Q37: Yes (Low) | R37: No | S37: No | T37: No | U37: Yes | V37: No | W37: No
A38: P0037 | B38: 46077 | C38: Liability | D38: 45-54 | E38: 7 | F38: 3 | G38: No | H38: 8,500-13,499 | I38: Hollywood (90028) | J38: $150,000+ | K38: No | L38: No | M38: No | N38: No | O38: =INDEX(CoverageTable[Deductible Applies],MATCH(Table18[[#This Row],[Coverage]],CoverageTable[Coverage],0)) -> No | P38: =INDEX(CoverageTable[Coverage Limit Applies],MATCH(Table18[[#This Row],[Coverage]],CoverageTable[Coverage],0)) -> Yes | Q38: No | R38: Yes (Low) | S38: No | T38: Yes | U38: No | V38: No | W38: No
A39: P0038 | B39: 46113 | C39: Liability | D39: 55-64 | E39: 2 | F39: 0 | G39: No | H39: 13,500-16,999 | I39: West Hollywood (90046) | J39: $45,000-$84,999 | K39: No | L39: No | M39: Yes | N39: No | O39: =INDEX(CoverageTable[Deductible Applies],MATCH(Table18[[#This Row],[Coverage]],CoverageTable[Coverage],0)) -> No | P39: =INDEX(CoverageTable[Coverage Limit Applies],MATCH(Table18[[#This Row],[Coverage]],CoverageTable[Coverage],0)) -> Yes | Q39: No | R39: Yes (Medium) | S39: No | T39: No | U39: No | V39: No | W39: No
A40: P0039 | B40: 46128 | C40: Liability | D40: 35-44 | E40: 6 | F40: 2 | G40: Yes (Low Score) | H40: 8,500-13,499 | I40: Cypress (90630) | J40: $85,000-$149,999 | K40: No | L40: No | M40: No | N40: Yes | O40: =INDEX(CoverageTable[Deductible Applies],MATCH(Table18[[#This Row],[Coverage]],CoverageTable[Coverage],0)) -> No | P40: =INDEX(CoverageTable[Coverage Limit Applies],MATCH(Table18[[#This Row],[Coverage]],CoverageTable[Coverage],0)) -> Yes | Q40: No | R40: Yes (Low) | S40: No | T40: No | U40: No | V40: No | W40: Yes
...

Sheet Premium Validation
A1: PolicyID | B1: Effective Date | C1: Coverage | D1: Ageband | E1: Years Driving | F1: At Fault Accidents | G1: Usage-Based Insurance | H1: Yearly Miles | I1: City/Zip Code | J1: Vehicle Price | K1: Exotic Car | L1: Difficult Parts | M1: High Theft Rate | N1: Advanced Safety Features | O1: Deductible Applies | P1: Coverage Limit Applies | Q1: Deductible | R1: Coverage Limit | S1: Good Student Discount | T1: Good Driver Discount | U1: Multi Policy Discount | V1: Loyal Customer Discount | W1: Organization Discount | X1: System-Generated Premium | Y1: Base Rate | Z1: Ageband Factor | AA1: Years Driving Factor | AB1: At Fault Accidents Factor | AC1: Usage Based Insurance Factor | AD1: Yearly Miles Factor | AE1: City/ Zip Code Factor | AF1: Vehicle Price Factor | AG1: Exotic Car Factor | AH1: Difficult Parts Factor | AI1: High Theft Rate Factor | AJ1: Advanced Safety Features Factor | AK1: Deductible Factor | AL1: Coverage Limit Factor | AM1: Good Student Factor | AN1: Good Driver Factor | AO1: Multi Policy Factor | AP1: Loyal Customer Factor | AQ1: Organization Factor | AR1: Rate Change Factor | AS1: Expected Premium | AT1: Difference | AU1: PASS/FAIL | AV1: Absolute Difference | AW1: Likely Issue
A2: P0001 | B2: 45908 | C2: Comprehensive | D2: 25-34 | E2: 1 | F2: 5+ | G2: Yes (Medium Score) | H2: 5,000-8,499 | I2: Costa Mesa (92626) | J2: $5,000-$14,999 | K2: No | L2: No | M2: No | N2: No | O2: =INDEX(CoverageTable[Deductible Applies],MATCH(Table1820[[#This Row],[Coverage]],CoverageTable[Coverage],0)) -> Yes | P2: =INDEX(CoverageTable[Coverage Limit Applies],MATCH(Table1820[[#This Row],[Coverage]],CoverageTable[Coverage],0)) -> No | Q2: Yes (Medium) | R2: No | S2: Yes | T2: No | U2: No | V2: No | W2: Yes | X2: 300.05622 | Y2: =_xlfn.XLOOKUP(Table1820[[#This Row],[Coverage]],CoverageTable[Coverage],CoverageTable[Base Rate],,0) -> 121 | Z2: =INDEX(Table16[Ageband Factor],MATCH(Table1820[[#This Row],[Ageband]],Table16[Ageband],0)) -> 1.23 | AA2: =VLOOKUP(Table1820[[#This Row],[Years Driving]],Table1[],2) -> 1.64 | AB2: =_xlfn.XLOOKUP(Table1820[[#This Row],[At Fault Accidents]],Table2[At Fault Accidents],Table2[At Fault Accident Factor],,0) -> 2.47 | AC2: =_xlfn.XLOOKUP(Table1820[[#This Row],[Usage-Based Insurance]],Table3[Usage-Based Insurance],Table3[Usage-Based Insurance Discount],,0) -> 0.8 | AD2: =_xlfn.XLOOKUP(Table1820[[#This Row],[Yearly Miles]],Table4[Yearly Miles],Table4[Yearly Miles Factor],,0) -> 0.93 | AE2: =_xlfn.XLOOKUP(Table1820[[#This Row],[City/Zip Code]],Table5[City/Zip Code],Table5[City/Zip Code Factor],,0) -> 0.92 | AF2: =_xlfn.XLOOKUP(Table1820[[#This Row],[Vehicle Price]],Table6[Vehicle Price],Table6[Vehicle Price Factor]) -> 0.97 | AG2: =_xlfn.XLOOKUP(Table1820[[#This Row],[Exotic Car]],Table7[Exotic Car],Table7[Exotic Car Factor],,0) -> 1 | AH2: =_xlfn.XLOOKUP(Table1820[[#This Row],[Difficult Parts]],Table8[Difficult Parts],Table8[Difficult Parts Factor],,0) -> 1 | AI2: =_xlfn.XLOOKUP(Table1820[[#This Row],[High Theft Rate]],Table9[High Theft Rate],Table9[High Theft Rate Factor],,0) -> 1 | AJ2: =_xlfn.XLOOKUP(Table1820[[#This Row],[Advanced Safety Features]],Table10[Advanced Safety Features],Table10[Advanced Safety Features Factor],,0) -> 1 | AK2: =_xlfn.XLOOKUP(Table1820[[#This Row],[Deductible]],Table12[Deductible],Table12[Deductible Factor],,0) -> 0.84 | AL2: =_xlfn.XLOOKUP(Table1820[[#This Row],[Coverage Limit]],Table13[Coverage Limit],Table13[Coverage Limit Factor],,0) -> 1 | AM2: =IF(Table1820[[#This Row],[Good Student Discount]]="Yes",'Rate Book'!$D$126,1) -> 0.92 | AN2: =IF(Table1820[[#This Row],[Good Driver Discount]]="Yes",'Rate Book'!$D$127,1) -> 1 | AO2: =IF(Table1820[[#This Row],[Multi Policy Discount]]="Yes",'Rate Book'!$D$128,1) -> 1 | AP2: =IF(Table1820[[#This Row],[Loyal Customer Discount]]="Yes",'Rate Book'!$D$129,1) -> 1 | AQ2: =IF(Table1820[[#This Row],[Organization Discount]]="Yes",'Rate Book'!$D$130,1) -> 0.97 | AR2: {=IF(Table1820[[#This Row],[Effective Date]]>=RateChangeTable[Effective Date],RateChangeTable[Rate Change Factor],1)} -> 1 | AS2: =PRODUCT(Table1820[[#This Row],[Base Rate]:[Rate Change Factor]]) -> 300.05622 | AT2: =Table1820[[#This Row],[System-Generated Premium]]-Table1820[[#This Row],[Expected Premium]] -> 0 | AU2: =IF(Table1820[[#This Row],[Difference]]=0,"PASS","FAIL") -> PASS | AV2: =ABS(Table1820[[#This Row],[Difference]]) -> 0 | AW2: No Issue
A3: P0002 | B3: 45889 | C3: Rental Car Reinbursement | D3: 16-24 | E3: 5 | F3: 4 | G3: No | H3: 8,500-13,499 | I3: West Hollywood (90046) | J3: $85,000-$149,999 | K3: No | L3: Yes | M3: No | N3: No | O3: =INDEX(CoverageTable[Deductible Applies],MATCH(Table1820[[#This Row],[Coverage]],CoverageTable[Coverage],0)) -> No | P3: =INDEX(CoverageTable[Coverage Limit Applies],MATCH(Table1820[[#This Row],[Coverage]],CoverageTable[Coverage],0)) -> Yes | Q3: No | R3: Yes (High) | S3: No | T3: No | U3: Yes | V3: No | W3: No | X3: 276.60397 | Y3: =_xlfn.XLOOKUP(Table1820[[#This Row],[Coverage]],CoverageTable[Coverage],CoverageTable[Base Rate],,0) -> 41 | Z3: =INDEX(Table16[Ageband Factor],MATCH(Table1820[[#This Row],[Ageband]],Table16[Ageband],0)) -> 1.32 | AA3: =VLOOKUP(Table1820[[#This Row],[Years Driving]],Table1[],2) -> 1.07 | AB3: =_xlfn.XLOOKUP(Table1820[[#This Row],[At Fault Accidents]],Table2[At Fault Accidents],Table2[At Fault Accident Factor],,0) -> 2.12 | AC3: =_xlfn.XLOOKUP(Table1820[[#This Row],[Usage-Based Insurance]],Table3[Usage-Based Insurance],Table3[Usage-Based Insurance Discount],,0) -> 1 | AD3: =_xlfn.XLOOKUP(Table1820[[#This Row],[Yearly Miles]],Table4[Yearly Miles],Table4[Yearly Miles Factor],,0) -> 1 | AE3: =_xlfn.XLOOKUP(Table1820[[#This Row],[City/Zip Code]],Table5[City/Zip Code],Table5[City/Zip Code Factor],,0) -> 1.18 | AF3: =_xlfn.XLOOKUP(Table1820[[#This Row],[Vehicle Price]],Table6[Vehicle Price],Table6[Vehicle Price Factor]) -> 2.02 | AG3: =_xlfn.XLOOKUP(Table1820[[#This Row],[Exotic Car]],Table7[Exotic Car],Table7[Exotic Car Factor],,0) -> 1 | AH3: =_xlfn.XLOOKUP(Table1820[[#This Row],[Difficult Parts]],Table8[Difficult Parts],Table8[Difficult Parts Factor],,0) -> 1.21 | AI3: =_xlfn.XLOOKUP(Table1820[[#This Row],[High Theft Rate]],Table9[High Theft Rate],Table9[High Theft Rate Factor],,0) -> 1 | AJ3: =_xlfn.XLOOKUP(Table1820[[#This Row],[Advanced Safety Features]],Table10[Advanced Safety Features],Table10[Advanced Safety Features Factor],,0) -> 1 | AK3: =_xlfn.XLOOKUP(Table1820[[#This Row],[Deductible]],Table12[Deductible],Table12[Deductible Factor],,0) -> 1 | AL3: =_xlfn.XLOOKUP(Table1820[[#This Row],[Coverage Limit]],Table13[Coverage Limit],Table13[Coverage Limit Factor],,0) -> 0.84 | AM3: =IF(Table1820[[#This Row],[Good Student Discount]]="Yes",'Rate Book'!$D$126,1) -> 1 | AN3: =IF(Table1820[[#This Row],[Good Driver Discount]]="Yes",'Rate Book'!$D$127,1) -> 1 | AO3: =IF(Table1820[[#This Row],[Multi Policy Discount]]="Yes",'Rate Book'!$D$128,1) -> 0.93 | AP3: =IF(Table1820[[#This Row],[Loyal Customer Discount]]="Yes",'Rate Book'!$D$129,1) -> 1 | AQ3: =IF(Table1820[[#This Row],[Organization Discount]]="Yes",'Rate Book'!$D$130,1) -> 1 | AR3: {=IF(Table1820[[#This Row],[Effective Date]]>=RateChangeTable[Effective Date],RateChangeTable[Rate Change Factor],1)} -> 1 | AS3: =PRODUCT(Table1820[[#This Row],[Base Rate]:[Rate Change Factor]]) -> 276.60397 | AT3: =Table1820[[#This Row],[System-Generated Premium]]-Table1820[[#This Row],[Expected Premium]] -> 0 | AU3: =IF(Table1820[[#This Row],[Difference]]=0,"PASS","FAIL") -> PASS | AV3: =ABS(Table1820[[#This Row],[Difference]]) -> 0 | AW3: No Issue
A4: P0003 | B4: 45946 | C4: Rental Car Reinbursement | D4: 55-64 | E4: 5 | F4: 5+ | G4: No | H4: 5,000-8,499 | I4: Anaheim (92801) | J4: $5,000-$14,999 | K4: No | L4: No | M4: No | N4: No | O4: =INDEX(CoverageTable[Deductible Applies],MATCH(Table1820[[#This Row],[Coverage]],CoverageTable[Coverage],0)) -> No | P4: =INDEX(CoverageTable[Coverage Limit Applies],MATCH(Table1820[[#This Row],[Coverage]],CoverageTable[Coverage],0)) -> Yes | Q4: No | R4: Yes (High) | S4: No | T4: No | U4: No | V4: No | W4: No | X4: 102.07974 | Y4: =_xlfn.XLOOKUP(Table1820[[#This Row],[Coverage]],CoverageTable[Coverage],CoverageTable[Base Rate],,0) -> 41 | Z4: =INDEX(Table16[Ageband Factor],MATCH(Table1820[[#This Row],[Ageband]],Table16[Ageband],0)) -> 1.12 | AA4: =VLOOKUP(Table1820[[#This Row],[Years Driving]],Table1[],2) -> 1.07 | AB4: =_xlfn.XLOOKUP(Table1820[[#This Row],[At Fault Accidents]],Table2[At Fault Accidents],Table2[At Fault Accident Factor],,0) -> 2.47 | AC4: =_xlfn.XLOOKUP(Table1820[[#This Row],[Usage-Based Insurance]],Table3[Usage-Based Insurance],Table3[Usage-Based Insurance Discount],,0) -> 1 | AD4: =_xlfn.XLOOKUP(Table1820[[#This Row],[Yearly Miles]],Table4[Yearly Miles],Table4[Yearly Miles Factor],,0) -> 0.93 | AE4: =_xlfn.XLOOKUP(Table1820[[#This Row],[City/Zip Code]],Table5[City/Zip Code],Table5[City/Zip Code Factor],,0) -> 1.11 | AF4: =_xlfn.XLOOKUP(Table1820[[#This Row],[Vehicle Price]],Table6[Vehicle Price],Table6[Vehicle Price Factor]) -> 0.97 | AG4: =_xlfn.XLOOKUP(Table1820[[#This Row],[Exotic Car]],Table7[Exotic Car],Table7[Exotic Car Factor],,0) -> 1 | AH4: =_xlfn.XLOOKUP(Table1820[[#This Row],[Difficult Parts]],Table8[Difficult Parts],Table8[Difficult Parts Factor],,0) -> 1 | AI4: =_xlfn.XLOOKUP(Table1820[[#This Row],[High Theft Rate]],Table9[High Theft Rate],Table9[High Theft Rate Factor],,0) -> 1 | AJ4: =_xlfn.XLOOKUP(Table1820[[#This Row],[Advanced Safety Features]],Table10[Advanced Safety Features],Table10[Advanced Safety Features Factor],,0) -> 1 | AK4: =_xlfn.XLOOKUP(Table1820[[#This Row],[Deductible]],Table12[Deductible],Table12[Deductible Factor],,0) -> 1 | AL4: =_xlfn.XLOOKUP(Table1820[[#This Row],[Coverage Limit]],Table13[Coverage Limit],Table13[Coverage Limit Factor],,0) -> 0.84 | AM4: =IF(Table1820[[#This Row],[Good Student Discount]]="Yes",'Rate Book'!$D$126,1) -> 1 | AN4: =IF(Table1820[[#This Row],[Good Driver Discount]]="Yes",'Rate Book'!$D$127,1) -> 1 | AO4: =IF(Table1820[[#This Row],[Multi Policy Discount]]="Yes",'Rate Book'!$D$128,1) -> 1 | AP4: =IF(Table1820[[#This Row],[Loyal Customer Discount]]="Yes",'Rate Book'!$D$129,1) -> 1 | AQ4: =IF(Table1820[[#This Row],[Organization Discount]]="Yes",'Rate Book'!$D$130,1) -> 1 | AR4: {=IF(Table1820[[#This Row],[Effective Date]]>=RateChangeTable[Effective Date],RateChangeTable[Rate Change Factor],1)} -> 1 | AS4: =PRODUCT(Table1820[[#This Row],[Base Rate]:[Rate Change Factor]]) -> 102.07974 | AT4: =Table1820[[#This Row],[System-Generated Premium]]-Table1820[[#This Row],[Expected Premium]] -> 0 | AU4: =IF(Table1820[[#This Row],[Difference]]=0,"PASS","FAIL") -> PASS | AV4: =ABS(Table1820[[#This Row],[Difference]]) -> 0 | AW4: No Issue
A5: P0004 | B5: 46106 | C5: Comprehensive | D5: 65+ | E5: 8+ | F5: 2 | G5: Yes (Medium Score) | H5: 17,000+ | I5: Westminster (92655) | J5: $0-$4,999 | K5: No | L5: No | M5: No | N5: Yes | O5: =INDEX(CoverageTable[Deductible Applies],MATCH(Table1820[[#This Row],[Coverage]],CoverageTable[Coverage],0)) -> Yes | P5: =INDEX(CoverageTable[Coverage Limit Applies],MATCH(Table1820[[#This Row],[Coverage]],CoverageTable[Coverage],0)) -> No | Q5: Yes (Low) | R5: No | S5: No | T5: Yes | U5: Yes | V5: No | W5: No | X5: 143.58 | Y5: =_xlfn.XLOOKUP(Table1820[[#This Row],[Coverage]],CoverageTable[Coverage],CoverageTable[Base Rate],,0) -> 121 | Z5: =INDEX(Table16[Ageband Factor],MATCH(Table1820[[#This Row],[Ageband]],Table16[Ageband],0)) -> 1.27 | AA5: =VLOOKUP(Table1820[[#This Row],[Years Driving]],Table1[],2) -> 0.93 | AB5: =_xlfn.XLOOKUP(Table1820[[#This Row],[At Fault Accidents]],Table2[At Fault Accidents],Table2[At Fault Accident Factor],,0) -> 1.55 | AC5: =_xlfn.XLOOKUP(Table1820[[#This Row],[Usage-Based Insurance]],Table3[Usage-Based Insurance],Table3[Usage-Based Insurance Discount],,0) -> 0.8 | AD5: =_xlfn.XLOOKUP(Table1820[[#This Row],[Yearly Miles]],Table4[Yearly Miles],Table4[Yearly Miles Factor],,0) -> 1.31 | AE5: =_xlfn.XLOOKUP(Table1820[[#This Row],[City/Zip Code]],Table5[City/Zip Code],Table5[City/Zip Code Factor],,0) -> 1.09 | AF5: =_xlfn.XLOOKUP(Table1820[[#This Row],[Vehicle Price]],Table6[Vehicle Price],Table6[Vehicle Price Factor]) -> 0.82 | AG5: =_xlfn.XLOOKUP(Table1820[[#This Row],[Exotic Car]],Table7[Exotic Car],Table7[Exotic Car Factor],,0) -> 1 | AH5: =_xlfn.XLOOKUP(Table1820[[#This Row],[Difficult Parts]],Table8[Difficult Parts],Table8[Difficult Parts Factor],,0) -> 1 | AI5: =_xlfn.XLOOKUP(Table1820[[#This Row],[High Theft Rate]],Table9[High Theft Rate],Table9[High Theft Rate Factor],,0) -> 1 | AJ5: =_xlfn.XLOOKUP(Table1820[[#This Row],[Advanced Safety Features]],Table10[Advanced Safety Features],Table10[Advanced Safety Features Factor],,0) -> 0.88 | AK5: =_xlfn.XLOOKUP(Table1820[[#This Row],[Deductible]],Table12[Deductible],Table12[Deductible Factor],,0) -> 0.95 | AL5: =_xlfn.XLOOKUP(Table1820[[#This Row],[Coverage Limit]],Table13[Coverage Limit],Table13[Coverage Limit Factor],,0) -> 1 | AM5: =IF(Table1820[[#This Row],[Good Student Discount]]="Yes",'Rate Book'!$D$126,1) -> 1 | AN5: =IF(Table1820[[#This Row],[Good Driver Discount]]="Yes",'Rate Book'!$D$127,1) -> 0.89 | AO5: =IF(Table1820[[#This Row],[Multi Policy Discount]]="Yes",'Rate Book'!$D$128,1) -> 0.93 | AP5: =IF(Table1820[[#This Row],[Loyal Customer Discount]]="Yes",'Rate Book'!$D$129,1) -> 1 | AQ5: =IF(Table1820[[#This Row],[Organization Discount]]="Yes",'Rate Book'!$D$130,1) -> 1 | AR5: {=IF(Table1820[[#This Row],[Effective Date]]>=RateChangeTable[Effective Date],RateChangeTable[Rate Change Factor],1)} -> 1.06 | AS5: =PRODUCT(Table1820[[#This Row],[Base Rate]:[Rate Change Factor]]) -> 152.19153 | AT5: =Table1820[[#This Row],[System-Generated Premium]]-Table1820[[#This Row],[Expected Premium]] -> -8.611525 | AU5: =IF(Table1820[[#This Row],[Difference]]=0,"PASS","FAIL") -> FAIL | AV5: =ABS(Table1820[[#This Row],[Difference]]) -> 8.611525 | AW5: Rate Change Factor not applied
A6: P0005 | B6: 46023 | C6: Collision | D6: 55-64 | E6: 7 | F6: 3 | G6: Yes (Medium Score) | H6: 13,500-16,999 | I6: Culver City (90066) | J6: $25,000-$44,999 | K6: No | L6: No | M6: No | N6: Yes | O6: =INDEX(CoverageTable[Deductible Applies],MATCH(Table1820[[#This Row],[Coverage]],CoverageTable[Coverage],0)) -> Yes | P6: =INDEX(CoverageTable[Coverage Limit Applies],MATCH(Table1820[[#This Row],[Coverage]],CoverageTable[Coverage],0)) -> No | Q6: Yes (Low) | R6: No | S6: No | T6: No | U6: Yes | V6: No | W6: No | X6: 1004.5837 | Y6: =_xlfn.XLOOKUP(Table1820[[#This Row],[Coverage]],CoverageTable[Coverage],CoverageTable[Base Rate],,0) -> 453 | Z6: =INDEX(Table16[Ageband Factor],MATCH(Table1820[[#This Row],[Ageband]],Table16[Ageband],0)) -> 1.12 | AA6: =VLOOKUP(Table1820[[#This Row],[Years Driving]],Table1[],2) -> 0.95 | AB6: =_xlfn.XLOOKUP(Table1820[[#This Row],[At Fault Accidents]],Table2[At Fault Accidents],Table2[At Fault Accident Factor],,0) -> 1.82 | AC6: =_xlfn.XLOOKUP(Table1820[[#This Row],[Usage-Based Insurance]],Table3[Usage-Based Insurance],Table3[Usage-Based Insurance Discount],,0) -> 0.8 | AD6: =_xlfn.XLOOKUP(Table1820[[#This Row],[Yearly Miles]],Table4[Yearly Miles],Table4[Yearly Miles Factor],,0) -> 1.18 | AE6: =_xlfn.XLOOKUP(Table1820[[#This Row],[City/Zip Code]],Table5[City/Zip Code],Table5[City/Zip Code Factor],,0) -> 1.15 | AF6: =_xlfn.XLOOKUP(Table1820[[#This Row],[Vehicle Price]],Table6[Vehicle Price],Table6[Vehicle Price Factor]) -> 1.28 | AG6: =_xlfn.XLOOKUP(Table1820[[#This Row],[Exotic Car]],Table7[Exotic Car],Table7[Exotic Car Factor],,0) -> 1 | AH6: =_xlfn.XLOOKUP(Table1820[[#This Row],[Difficult Parts]],Table8[Difficult Parts],Table8[Difficult Parts Factor],,0) -> 1 | AI6: =_xlfn.XLOOKUP(Table1820[[#This Row],[High Theft Rate]],Table9[High Theft Rate],Table9[High Theft Rate Factor],,0) -> 1 | AJ6: =_xlfn.XLOOKUP(Table1820[[#This Row],[Advanced Safety Features]],Table10[Advanced Safety Features],Table10[Advanced Safety Features Factor],,0) -> 0.88 | AK6: =_xlfn.XLOOKUP(Table1820[[#This Row],[Deductible]],Table12[Deductible],Table12[Deductible Factor],,0) -> 0.95 | AL6: =_xlfn.XLOOKUP(Table1820[[#This Row],[Coverage Limit]],Table13[Coverage Limit],Table13[Coverage Limit Factor],,0) -> 1 | AM6: =IF(Table1820[[#This Row],[Good Student Discount]]="Yes",'Rate Book'!$D$126,1) -> 1 | AN6: =IF(Table1820[[#This Row],[Good Driver Discount]]="Yes",'Rate Book'!$D$127,1) -> 1 | AO6: =IF(Table1820[[#This Row],[Multi Policy Discount]]="Yes",'Rate Book'!$D$128,1) -> 0.93 | AP6: =IF(Table1820[[#This Row],[Loyal Customer Discount]]="Yes",'Rate Book'!$D$129,1) -> 1 | AQ6: =IF(Table1820[[#This Row],[Organization Discount]]="Yes",'Rate Book'!$D$130,1) -> 1 | AR6: {=IF(Table1820[[#This Row],[Effective Date]]>=RateChangeTable[Effective Date],RateChangeTable[Rate Change Factor],1)} -> 1.06 | AS6: =PRODUCT(Table1820[[#This Row],[Base Rate]:[Rate Change Factor]]) -> 1004.5837 | AT6: =Table1820[[#This Row],[System-Generated Premium]]-Table1820[[#This Row],[Expected Premium]] -> 0 | AU6: =IF(Table1820[[#This Row],[Difference]]=0,"PASS","FAIL") -> PASS | AV6: =ABS(Table1820[[#This Row],[Difference]]) -> 0 | AW6: No Issue
A7: P0006 | B7: 45924 | C7: Collision | D7: 25-34 | E7: 8+ | F7: 4 | G7: No | H7: 17,000+ | I7: Westminster (92655) | J7: $5,000-$14,999 | K7: No | L7: No | M7: No | N7: No | O7: =INDEX(CoverageTable[Deductible Applies],MATCH(Table1820[[#This Row],[Coverage]],CoverageTable[Coverage],0)) -> Yes | P7: =INDEX(CoverageTable[Coverage Limit Applies],MATCH(Table1820[[#This Row],[Coverage]],CoverageTable[Coverage],0)) -> No | Q7: Yes (High) | R7: No | S7: No | T7: No | U7: No | V7: No | W7: No | X7: 1095.5297 | Y7: =_xlfn.XLOOKUP(Table1820[[#This Row],[Coverage]],CoverageTable[Coverage],CoverageTable[Base Rate],,0) -> 453 | Z7: =INDEX(Table16[Ageband Factor],MATCH(Table1820[[#This Row],[Ageband]],Table16[Ageband],0)) -> 1.23 | AA7: =VLOOKUP(Table1820[[#This Row],[Years Driving]],Table1[],2) -> 0.93 | AB7: =_xlfn.XLOOKUP(Table1820[[#This Row],[At Fault Accidents]],Table2[At Fault Accidents],Table2[At Fault Accident Factor],,0) -> 2.12 | AC7: =_xlfn.XLOOKUP(Table1820[[#This Row],[Usage-Based Insurance]],Table3[Usage-Based Insurance],Table3[Usage-Based Insurance Discount],,0) -> 1 | AD7: =_xlfn.XLOOKUP(Table1820[[#This Row],[Yearly Miles]],Table4[Yearly Miles],Table4[Yearly Miles Factor],,0) -> 1.31 | AE7: =_xlfn.XLOOKUP(Table1820[[#This Row],[City/Zip Code]],Table5[City/Zip Code],Table5[City/Zip Code Factor],,0) -> 1.09 | AF7: =_xlfn.XLOOKUP(Table1820[[#This Row],[Vehicle Price]],Table6[Vehicle Price],Table6[Vehicle Price Factor]) -> 0.97 | AG7: =_xlfn.XLOOKUP(Table1820[[#This Row],[Exotic Car]],Table7[Exotic Car],Table7[Exotic Car Factor],,0) -> 1 | AH7: =_xlfn.XLOOKUP(Table1820[[#This Row],[Difficult Parts]],Table8[Difficult Parts],Table8[Difficult Parts Factor],,0) -> 1 | AI7: =_xlfn.XLOOKUP(Table1820[[#This Row],[High Theft Rate]],Table9[High Theft Rate],Table9[High Theft Rate Factor],,0) -> 1 | AJ7: =_xlfn.XLOOKUP(Table1820[[#This Row],[Advanced Safety Features]],Table10[Advanced Safety Features],Table10[Advanced Safety Features Factor],,0) -> 1 | AK7: =_xlfn.XLOOKUP(Table1820[[#This Row],[Deductible]],Table12[Deductible],Table12[Deductible Factor],,0) -> 0.72 | AL7: =_xlfn.XLOOKUP(Table1820[[#This Row],[Coverage Limit]],Table13[Coverage Limit],Table13[Coverage Limit Factor],,0) -> 1 | AM7: =IF(Table1820[[#This Row],[Good Student Discount]]="Yes",'Rate Book'!$D$126,1) -> 1 | AN7: =IF(Table1820[[#This Row],[Good Driver Discount]]="Yes",'Rate Book'!$D$127,1) -> 1 | AO7: =IF(Table1820[[#This Row],[Multi Policy Discount]]="Yes",'Rate Book'!$D$128,1) -> 1 | AP7: =IF(Table1820[[#This Row],[Loyal Customer Discount]]="Yes",'Rate Book'!$D$129,1) -> 1 | AQ7: =IF(Table1820[[#This Row],[Organization Discount]]="Yes",'Rate Book'!$D$130,1) -> 1 | AR7: {=IF(Table1820[[#This Row],[Effective Date]]>=RateChangeTable[Effective Date],RateChangeTable[Rate Change Factor],1)} -> 1 | AS7: =PRODUCT(Table1820[[#This Row],[Base Rate]:[Rate Change Factor]]) -> 1095.5297 | AT7: =Table1820[[#This Row],[System-Generated Premium]]-Table1820[[#This Row],[Expected Premium]] -> 0 | AU7: =IF(Table1820[[#This Row],[Difference]]=0,"PASS","FAIL") -> PASS | AV7: =ABS(Table1820[[#This Row],[Difference]]) -> 0 | AW7: No Issue
A8: P0007 | B8: 46120 | C8: Rental Car Reinbursement | D8: 35-44 | E8: 5 | F8: 3 | G8: No | H8: 0-4,999 | I8: Silverlake (90026 ) | J8: $85,000-$149,999 | K8: No | L8: No | M8: No | N8: No | O8: =INDEX(CoverageTable[Deductible Applies],MATCH(Table1820[[#This Row],[Coverage]],CoverageTable[Coverage],0)) -> No | P8: =INDEX(CoverageTable[Coverage Limit Applies],MATCH(Table1820[[#This Row],[Coverage]],CoverageTable[Coverage],0)) -> Yes | Q8: No | R8: Yes (Low) | S8: No | T8: No | U8: No | V8: No | W8: No | X8: 99.196862 | Y8: =_xlfn.XLOOKUP(Table1820[[#This Row],[Coverage]],CoverageTable[Coverage],CoverageTable[Base Rate],,0) -> 41 | Z8: =INDEX(Table16[Ageband Factor],MATCH(Table1820[[#This Row],[Ageband]],Table16[Ageband],0)) -> 1 | AA8: =VLOOKUP(Table1820[[#This Row],[Years Driving]],Table1[],2) -> 1.07 | AB8: =_xlfn.XLOOKUP(Table1820[[#This Row],[At Fault Accidents]],Table2[At Fault Accidents],Table2[At Fault Accident Factor],,0) -> 1.82 | AC8: =_xlfn.XLOOKUP(Table1820[[#This Row],[Usage-Based Insurance]],Table3[Usage-Based Insurance],Table3[Usage-Based Insurance Discount],,0) -> 1 | AD8: =_xlfn.XLOOKUP(Table1820[[#This Row],[Yearly Miles]],Table4[Yearly Miles],Table4[Yearly Miles Factor],,0) -> 0.82 | AE8: =_xlfn.XLOOKUP(Table1820[[#This Row],[City/Zip Code]],Table5[City/Zip Code],Table5[City/Zip Code Factor],,0) -> 1.16 | AF8: =_xlfn.XLOOKUP(Table1820[[#This Row],[Vehicle Price]],Table6[Vehicle Price],Table6[Vehicle Price Factor]) -> 2.02 | AG8: =_xlfn.XLOOKUP(Table1820[[#This Row],[Exotic Car]],Table7[Exotic Car],Table7[Exotic Car Factor],,0) -> 1 | AH8: =_xlfn.XLOOKUP(Table1820[[#This Row],[Difficult Parts]],Table8[Difficult Parts],Table8[Difficult Parts Factor],,0) -> 1 | AI8: =_xlfn.XLOOKUP(Table1820[[#This Row],[High Theft Rate]],Table9[High Theft Rate],Table9[High Theft Rate Factor],,0) -> 1 | AJ8: =_xlfn.XLOOKUP(Table1820[[#This Row],[Advanced Safety Features]],Table10[Advanced Safety Features],Table10[Advanced Safety Features Factor],,0) -> 1 | AK8: =_xlfn.XLOOKUP(Table1820[[#This Row],[Deductible]],Table12[Deductible],Table12[Deductible Factor],,0) -> 1 | AL8: =_xlfn.XLOOKUP(Table1820[[#This Row],[Coverage Limit]],Table13[Coverage Limit],Table13[Coverage Limit Factor],,0) -> 0.61 | AM8: =IF(Table1820[[#This Row],[Good Student Discount]]="Yes",'Rate Book'!$D$126,1) -> 1 | AN8: =IF(Table1820[[#This Row],[Good Driver Discount]]="Yes",'Rate Book'!$D$127,1) -> 1 | AO8: =IF(Table1820[[#This Row],[Multi Policy Discount]]="Yes",'Rate Book'!$D$128,1) -> 1 | AP8: =IF(Table1820[[#This Row],[Loyal Customer Discount]]="Yes",'Rate Book'!$D$129,1) -> 1 | AQ8: =IF(Table1820[[#This Row],[Organization Discount]]="Yes",'Rate Book'!$D$130,1) -> 1 | AR8: {=IF(Table1820[[#This Row],[Effective Date]]>=RateChangeTable[Effective Date],RateChangeTable[Rate Change Factor],1)} -> 1.06 | AS8: =PRODUCT(Table1820[[#This Row],[Base Rate]:[Rate Change Factor]]) -> 99.196862 | AT8: =Table1820[[#This Row],[System-Generated Premium]]-Table1820[[#This Row],[Expected Premium]] -> 0 | AU8: =IF(Table1820[[#This Row],[Difference]]=0,"PASS","FAIL") -> PASS | AV8: =ABS(Table1820[[#This Row],[Difference]]) -> 0 | AW8: No Issue
A9: P0008 | B9: 46143 | C9: Liability | D9: 25-34 | E9: 7 | F9: 2 | G9: Yes (Medium Score) | H9: 8,500-13,499 | I9: Compton (90220) | J9: $45,000-$84,999 | K9: No | L9: No | M9: No | N9: Yes | O9: =INDEX(CoverageTable[Deductible Applies],MATCH(Table1820[[#This Row],[Coverage]],CoverageTable[Coverage],0)) -> No | P9: =INDEX(CoverageTable[Coverage Limit Applies],MATCH(Table1820[[#This Row],[Coverage]],CoverageTable[Coverage],0)) -> Yes | Q9: No | R9: Yes (Medium) | S9: Yes | T9: No | U9: No | V9: No | W9: No | X9: 1363.8729 | Y9: =_xlfn.XLOOKUP(Table1820[[#This Row],[Coverage]],CoverageTable[Coverage],CoverageTable[Base Rate],,0) -> 622 | Z9: =INDEX(Table16[Ageband Factor],MATCH(Table1820[[#This Row],[Ageband]],Table16[Ageband],0)) -> 1.23 | AA9: =VLOOKUP(Table1820[[#This Row],[Years Driving]],Table1[],2) -> 0.95 | AB9: =_xlfn.XLOOKUP(Table1820[[#This Row],[At Fault Accidents]],Table2[At Fault Accidents],Table2[At Fault Accident Factor],,0) -> 1.55 | AC9: =_xlfn.XLOOKUP(Table1820[[#This Row],[Usage-Based Insurance]],Table3[Usage-Based Insurance],Table3[Usage-Based Insurance Discount],,0) -> 0.8 | AD9: =_xlfn.XLOOKUP(Table1820[[#This Row],[Yearly Miles]],Table4[Yearly Miles],Table4[Yearly Miles Factor],,0) -> 1 | AE9: =_xlfn.XLOOKUP(Table1820[[#This Row],[City/Zip Code]],Table5[City/Zip Code],Table5[City/Zip Code Factor],,0) -> 1.56 | AF9: =_xlfn.XLOOKUP(Table1820[[#This Row],[Vehicle Price]],Table6[Vehicle Price],Table6[Vehicle Price Factor]) -> 1.57 | AG9: =_xlfn.XLOOKUP(Table1820[[#This Row],[Exotic Car]],Table7[Exotic Car],Table7[Exotic Car Factor],,0) -> 1 | AH9: =_xlfn.XLOOKUP(Table1820[[#This Row],[Difficult Parts]],Table8[Difficult Parts],Table8[Difficult Parts Factor],,0) -> 1 | AI9: =_xlfn.XLOOKUP(Table1820[[#This Row],[High Theft Rate]],Table9[High Theft Rate],Table9[High Theft Rate Factor],,0) -> 1 | AJ9: =_xlfn.XLOOKUP(Table1820[[#This Row],[Advanced Safety Features]],Table10[Advanced Safety Features],Table10[Advanced Safety Features Factor],,0) -> 0.88 | AK9: =_xlfn.XLOOKUP(Table1820[[#This Row],[Deductible]],Table12[Deductible],Table12[Deductible Factor],,0) -> 1 | AL9: =_xlfn.XLOOKUP(Table1820[[#This Row],[Coverage Limit]],Table13[Coverage Limit],Table13[Coverage Limit Factor],,0) -> 0.72 | AM9: =IF(Table1820[[#This Row],[Good Student Discount]]="Yes",'Rate Book'!$D$126,1) -> 0.92 | AN9: =IF(Table1820[[#This Row],[Good Driver Discount]]="Yes",'Rate Book'!$D$127,1) -> 1 | AO9: =IF(Table1820[[#This Row],[Multi Policy Discount]]="Yes",'Rate Book'!$D$128,1) -> 1 | AP9: =IF(Table1820[[#This Row],[Loyal Customer Discount]]="Yes",'Rate Book'!$D$129,1) -> 1 | AQ9: =IF(Table1820[[#This Row],[Organization Discount]]="Yes",'Rate Book'!$D$130,1) -> 1 | AR9: {=IF(Table1820[[#This Row],[Effective Date]]>=RateChangeTable[Effective Date],RateChangeTable[Rate Change Factor],1)} -> 1.06 | AS9: =PRODUCT(Table1820[[#This Row],[Base Rate]:[Rate Change Factor]]) -> 1363.8729 | AT9: =Table1820[[#This Row],[System-Generated Premium]]-Table1820[[#This Row],[Expected Premium]] -> 0 | AU9: =IF(Table1820[[#This Row],[Difference]]=0,"PASS","FAIL") -> PASS | AV9: =ABS(Table1820[[#This Row],[Difference]]) -> 0 | AW9: No Issue
A10: P0009 | B10: 46072 | C10: Liability | D10: 35-44 | E10: 6 | F10: 3 | G10: Yes (High Score) | H10: 17,000+ | I10: Newport Beach (92603) | J10: $85,000-$149,999 | K10: No | L10: No | M10: No | N10: No | O10: =INDEX(CoverageTable[Deductible Applies],MATCH(Table1820[[#This Row],[Coverage]],CoverageTable[Coverage],0)) -> No | P10: =INDEX(CoverageTable[Coverage Limit Applies],MATCH(Table1820[[#This Row],[Coverage]],CoverageTable[Coverage],0)) -> Yes | Q10: No | R10: Yes (Medium) | S10: Yes | T10: Yes | U10: Yes | V10: No | W10: Yes | X10: 1031.8024 | Y10: =_xlfn.XLOOKUP(Table1820[[#This Row],[Coverage]],CoverageTable[Coverage],CoverageTable[Base Rate],,0) -> 622 | Z10: =INDEX(Table16[Ageband Factor],MATCH(Table1820[[#This Row],[Ageband]],Table16[Ageband],0)) -> 1 | AA10: =VLOOKUP(Table1820[[#This Row],[Years Driving]],Table1[],2) -> 1 | AB10: =_xlfn.XLOOKUP(Table1820[[#This Row],[At Fault Accidents]],Table2[At Fault Accidents],Table2[At Fault Accident Factor],,0) -> 1.82 | AC10: =_xlfn.XLOOKUP(Table1820[[#This Row],[Usage-Based Insurance]],Table3[Usage-Based Insurance],Table3[Usage-Based Insurance Discount],,0) -> 0.65 | AD10: =_xlfn.XLOOKUP(Table1820[[#This Row],[Yearly Miles]],Table4[Yearly Miles],Table4[Yearly Miles Factor],,0) -> 1.31 | AE10: =_xlfn.XLOOKUP(Table1820[[#This Row],[City/Zip Code]],Table5[City/Zip Code],Table5[City/Zip Code Factor],,0) -> 0.94 | AF10: =_xlfn.XLOOKUP(Table1820[[#This Row],[Vehicle Price]],Table6[Vehicle Price],Table6[Vehicle Price Factor]) -> 2.02 | AG10: =_xlfn.XLOOKUP(Table1820[[#This Row],[Exotic Car]],Table7[Exotic Car],Table7[Exotic Car Factor],,0) -> 1 | AH10: =_xlfn.XLOOKUP(Table1820[[#This Row],[Difficult Parts]],Table8[Difficult Parts],Table8[Difficult Parts Factor],,0) -> 1 | AI10: =_xlfn.XLOOKUP(Table1820[[#This Row],[High Theft Rate]],Table9[High Theft Rate],Table9[High Theft Rate Factor],,0) -> 1 | AJ10: =_xlfn.XLOOKUP(Table1820[[#This Row],[Advanced Safety Features]],Table10[Advanced Safety Features],Table10[Advanced Safety Features Factor],,0) -> 1 | AK10: =_xlfn.XLOOKUP(Table1820[[#This Row],[Deductible]],Table12[Deductible],Table12[Deductible Factor],,0) -> 1 | AL10: =_xlfn.XLOOKUP(Table1820[[#This Row],[Coverage Limit]],Table13[Coverage Limit],Table13[Coverage Limit Factor],,0) -> 0.72 | AM10: =IF(Table1820[[#This Row],[Good Student Discount]]="Yes",'Rate Book'!$D$126,1) -> 0.92 | AN10: =IF(Table1820[[#This Row],[Good Driver Discount]]="Yes",'Rate Book'!$D$127,1) -> 0.89 | AO10: =IF(Table1820[[#This Row],[Multi Policy Discount]]="Yes",'Rate Book'!$D$128,1) -> 0.93 | AP10: =IF(Table1820[[#This Row],[Loyal Customer Discount]]="Yes",'Rate Book'!$D$129,1) -> 1 | AQ10: =IF(Table1820[[#This Row],[Organization Discount]]="Yes",'Rate Book'!$D$130,1) -> 0.97 | AR10: {=IF(Table1820[[#This Row],[Effective Date]]>=RateChangeTable[Effective Date],RateChangeTable[Rate Change Factor],1)} -> 1.06 | AS10: =PRODUCT(Table1820[[#This Row],[Base Rate]:[Rate Change Factor]]) -> 1031.8024 | AT10: =Table1820[[#This Row],[System-Generated Premium]]-Table1820[[#This Row],[Expected Premium]] -> 0 | AU10: =IF(Table1820[[#This Row],[Difference]]=0,"PASS","FAIL") -> PASS | AV10: =ABS(Table1820[[#This Row],[Difference]]) -> 0 | AW10: No Issue
A11: P0010 | B11: 45997 | C11: Liability | D11: 25-34 | E11: 8+ | F11: 2 | G11: No | H11: 5,000-8,499 | I11: Huntington Beach (90742) | J11: $15,000-$24,999 | K11: No | L11: No | M11: No | N11: No | O11: =INDEX(CoverageTable[Deductible Applies],MATCH(Table1820[[#This Row],[Coverage]],CoverageTable[Coverage],0)) -> No | P11: =INDEX(CoverageTable[Coverage Limit Applies],MATCH(Table1820[[#This Row],[Coverage]],CoverageTable[Coverage],0)) -> Yes | Q11: No | R11: Yes (Medium) | S11: No | T11: No | U11: No | V11: No | W11: Yes | X11: 758.13606 | Y11: =_xlfn.XLOOKUP(Table1820[[#This Row],[Coverage]],CoverageTable[Coverage],CoverageTable[Base Rate],,0) -> 622 | Z11: =INDEX(Table16[Ageband Factor],MATCH(Table1820[[#This Row],[Ageband]],Table16[Ageband],0)) -> 1.23 | AA11: =VLOOKUP(Table1820[[#This Row],[Years Driving]],Table1[],2) -> 0.93 | AB11: =_xlfn.XLOOKUP(Table1820[[#This Row],[At Fault Accidents]],Table2[At Fault Accidents],Table2[At Fault Accident Factor],,0) -> 1.55 | AC11: =_xlfn.XLOOKUP(Table1820[[#This Row],[Usage-Based Insurance]],Table3[Usage-Based Insurance],Table3[Usage-Based Insurance Discount],,0) -> 1 | AD11: =_xlfn.XLOOKUP(Table1820[[#This Row],[Yearly Miles]],Table4[Yearly Miles],Table4[Yearly Miles Factor],,0) -> 0.93 | AE11: =_xlfn.XLOOKUP(Table1820[[#This Row],[City/Zip Code]],Table5[City/Zip Code],Table5[City/Zip Code Factor],,0) -> 0.98 | AF11: =_xlfn.XLOOKUP(Table1820[[#This Row],[Vehicle Price]],Table6[Vehicle Price],Table6[Vehicle Price Factor]) -> 1.08 | AG11: =_xlfn.XLOOKUP(Table1820[[#This Row],[Exotic Car]],Table7[Exotic Car],Table7[Exotic Car Factor],,0) -> 1 | AH11: =_xlfn.XLOOKUP(Table1820[[#This Row],[Difficult Parts]],Table8[Difficult Parts],Table8[Difficult Parts Factor],,0) -> 1 | AI11: =_xlfn.XLOOKUP(Table1820[[#This Row],[High Theft Rate]],Table9[High Theft Rate],Table9[High Theft Rate Factor],,0) -> 1 | AJ11: =_xlfn.XLOOKUP(Table1820[[#This Row],[Advanced Safety Features]],Table10[Advanced Safety Features],Table10[Advanced Safety Features Factor],,0) -> 1 | AK11: =_xlfn.XLOOKUP(Table1820[[#This Row],[Deductible]],Table12[Deductible],Table12[Deductible Factor],,0) -> 1 | AL11: =_xlfn.XLOOKUP(Table1820[[#This Row],[Coverage Limit]],Table13[Coverage Limit],Table13[Coverage Limit Factor],,0) -> 0.72 | AM11: =IF(Table1820[[#This Row],[Good Student Discount]]="Yes",'Rate Book'!$D$126,1) -> 1 | AN11: =IF(Table1820[[#This Row],[Good Driver Discount]]="Yes",'Rate Book'!$D$127,1) -> 1 | AO11: =IF(Table1820[[#This Row],[Multi Policy Discount]]="Yes",'Rate Book'!$D$128,1) -> 1 | AP11: =IF(Table1820[[#This Row],[Loyal Customer Discount]]="Yes",'Rate Book'!$D$129,1) -> 1 | AQ11: =IF(Table1820[[#This Row],[Organization Discount]]="Yes",'Rate Book'!$D$130,1) -> 0.97 | AR11: {=IF(Table1820[[#This Row],[Effective Date]]>=RateChangeTable[Effective Date],RateChangeTable[Rate Change Factor],1)} -> 1 | AS11: =PRODUCT(Table1820[[#This Row],[Base Rate]:[Rate Change Factor]]) -> 758.13606 | AT11: =Table1820[[#This Row],[System-Generated Premium]]-Table1820[[#This Row],[Expected Premium]] -> 0 | AU11: =IF(Table1820[[#This Row],[Difference]]=0,"PASS","FAIL") -> PASS | AV11: =ABS(Table1820[[#This Row],[Difference]]) -> 0 | AW11: No Issue
